<?xml version="1.0" ?>
<robot name="atlas" xmlns:xacro="http://www.ros.org/wiki/xacro" DoF="6" RobotModel="Atlas inertial left foot">



  <!--                                                              Joints                                                          -->



  <joint name="l_leg_akx" type="revolute">
    <parent link="l_foot"/>
    <child link="l_talus"/>
    <origin rpy="0 0 0" xyz="0 0 0"/>
    <axis xyz="1 0 0"/>
    <limit effort="360" lower="-0.8" upper="0.8" velocity="12"/>
  </joint>

  <joint name="l_leg_aky" type="revolute">
    <parent link="l_talus"/>
    <child link="l_lleg"/>
    <origin rpy="0 0 0" xyz="0 0 0"/>
    <axis xyz="0 1 0"/>
    <limit effort="740" lower="-0.7" upper="1" velocity="12"/>
  </joint>

  <joint name="l_leg_kny" type="revolute">
    <parent link="l_lleg"/>
    <child link="l_uleg"/>
    <origin rpy="0 0 0" xyz="0 0 0.422"/>
    <axis xyz="0 1 0"/>
    <limit effort="890" lower="-2.35637" upper="0" velocity="12"/>
  </joint>

  <joint name="l_leg_hpy" type="revolute">
    <parent link="l_uleg"/>
    <child link="l_lglut"/>
    <origin rpy="0 0 0" xyz="0.05 0 0.374"/>
    <axis xyz="0 1 0"/>
    <limit effort="840" lower="-0.65764" upper="1.61234" velocity="12"/>
  </joint>

  <joint name="l_leg_hpx" type="revolute">
    <parent link="l_lglut"/>
    <child link="l_uglut"/>
    <origin rpy="0 0 0" xyz="-0.05 -0.0225 0.066"/>
    <axis xyz="1 0 0"/>
    <limit effort="530" lower="-0.523599" upper="0.523599" velocity="12"/>
  </joint>

  <joint name="l_leg_hpz" type="revolute">
    <parent link="l_uglut"/>
    <child link="pelvis"/>
    <origin rpy="0 0 0" xyz="0 0 0"/>
    <axis xyz="0 0 1"/>
    <limit effort="275" lower="-0.786794" upper="0.174358" velocity="12"/>
  </joint>



  <joint name="back_bkz" type="revolute">
    <parent link="pelvis"/>
    <child link="ltorso"/>
    <origin rpy="0 0 0" xyz="-0.0125 -0.089 0"/>
    <axis xyz="0 0 1"/>
    <limit effort="106" lower="-0.663225" upper="0.663225" velocity="12"/>
  </joint>

  <joint name="back_bky" type="revolute">
    <parent link="ltorso"/>
    <child link="mtorso"/>
    <origin rpy="0 0 0" xyz="0 0 0.162"/>
    <axis xyz="0 1 0"/>
    <limit effort="445" lower="-0.219388" upper="0.538783" velocity="9"/>
  </joint>

  <joint name="back_bkx" type="revolute">
    <parent link="mtorso"/>
    <child link="utorso"/>
    <origin rpy="0 0 0" xyz="0 0 0.05"/>
    <axis xyz="1 0 0"/>
    <limit effort="300" lower="-0.523599" upper="0.523599" velocity="12"/>
  </joint>



  <joint name="l_arm_shz" type="revolute">
    <parent link="utorso"/>
    <child link="l_clav"/>
    <origin rpy="0 0 0" xyz="0.1406 0.2256 0.4776"/>
    <axis xyz="0 0 1"/>
    <limit effort="87" lower="-1.5708" upper="0.785398" velocity="12"/>
  </joint>

  <joint name="l_arm_shx" type="revolute">
    <parent link="l_clav"/>
    <child link="l_scap"/>
    <origin rpy="0 0 0" xyz="0 0.11 -0.245"/>
    <axis xyz="1 0 0"/>
    <limit effort="99" lower="-1.5708" upper="1.5708" velocity="12"/>
  </joint>

  <joint name="l_arm_ely" type="revolute">
    <parent link="l_scap"/>
    <child link="l_uarm"/>
    <origin rpy="0 0 0" xyz="0 0.187 -0.016"/>
    <axis xyz="0 1 0"/>
    <limit effort="63" lower="0" upper="3.14159" velocity="12"/>
  </joint>

  <joint name="l_arm_elx" type="revolute">
    <parent link="l_uarm"/>
    <child link="l_larm"/>
    <origin rpy="0 0 0" xyz="0 0.119 0.0092"/>
    <axis xyz="1 0 0"/>
    <limit effort="112" lower="0" upper="2.35619" velocity="12"/>
  </joint>

  <joint name="l_arm_uwy" type="revolute">
    <parent link="l_larm"/>
    <child link="l_ufarm"/>
    <origin rpy="0 0 0" xyz="0 0.29955 -0.00921"/>
    <axis xyz="0 1 0"/>
    <limit effort="25" lower="-3.011" upper="3.011" velocity="10"/>
  </joint>

  <joint name="l_arm_mwx" type="revolute">
    <parent link="l_ufarm"/>
    <child link="l_lfarm"/>
    <origin rpy="0 0 0" xyz="0 0 0"/>
    <axis xyz="1 0 0"/>
    <limit effort="25" lower="-1.7628" upper="1.7628" velocity="10"/>
  </joint>

  <joint name="l_arm_lwy" type="revolute">
    <parent link="l_lfarm"/>
    <child link="l_hand"/>
    <origin rpy="0 0 0" xyz="0 0 0"/>
    <axis xyz="0 1 0"/>
    <limit effort="25" lower="-2.9671" upper="2.9671" velocity="10"/>
  </joint>



  <joint name="neck_ay" type="revolute">
    <parent link="utorso"/>
    <child link="head"/>
    <origin rpy="0 0 0" xyz="0.2546 0 0.6215"/>
    <axis xyz="0 1 0"/>
    <limit effort="25" lower="-0.602139" upper="1.14319" velocity="6.28"/>
  </joint>



  <joint name="r_arm_shz" type="revolute">
    <parent link="utorso"/>
    <child link="r_clav"/>
    <origin rpy="0 0 0" xyz="0.1406 -0.2256 0.4776"/>
    <axis xyz="0 0 1"/>
    <limit effort="87" lower="-0.785398" upper="1.5708" velocity="12"/>
  </joint>

  <joint name="r_arm_shx" type="revolute">
    <parent link="r_clav"/>
    <child link="r_scap"/>
    <origin rpy="0 0 0" xyz="0 -0.11 -0.245"/>
    <axis xyz="1 0 0"/>
    <limit effort="99" lower="-1.5708" upper="1.5708" velocity="12"/>
  </joint>

  <joint name="r_arm_ely" type="revolute">
    <parent link="r_scap"/>
    <child link="r_uarm"/>
    <origin rpy="0 0 0" xyz="0 -0.187 -0.016"/>
    <axis xyz="0 1 0"/>
    <limit effort="63" lower="0" upper="3.14159" velocity="12"/>
  </joint>  

  <joint name="r_arm_elx" type="revolute">
    <parent link="r_uarm"/>
    <child link="r_larm"/>
    <origin rpy="0 0 0" xyz="0 -0.119 0.0092"/>
    <axis xyz="1 0 0"/>
    <limit effort="112" lower="-2.35619" upper="0" velocity="12"/>
  </joint>

  <joint name="r_arm_uwy" type="revolute">
    <parent link="r_larm"/>
    <child link="r_ufarm"/>
    <origin rpy="0 0 0" xyz="0 -0.29955 -0.00921"/>
    <axis xyz="0 1 0"/>
    <limit effort="25" lower="-3.011" upper="3.011" velocity="10"/>
  </joint>

  <joint name="r_arm_mwx" type="revolute">
    <parent link="r_ufarm"/>
    <child link="r_lfarm"/>
    <origin rpy="0 0 0" xyz="0 0 0"/>
    <axis xyz="1 0 0"/>
    <limit effort="25" lower="-1.7628" upper="1.7628" velocity="10"/>
  </joint>

  <joint name="r_arm_lwy" type="revolute">
    <parent link="r_lfarm"/>
    <child link="r_hand"/>
    <origin rpy="0 0 0" xyz="0 0 0"/>
    <axis xyz="0 1 0"/>
    <limit effort="25" lower="-2.9671" upper="2.9671" velocity="10"/>
  </joint>



  <joint name="r_leg_hpz" type="revolute">
    <parent link="pelvis"/>
    <child link="r_uglut"/>
    <origin rpy="0 0 0" xyz="0 -0.178 0"/>
    <axis xyz="0 0 1"/>
    <limit effort="275" lower="-0.786794" upper="0.174358" velocity="12"/>
  </joint>

  <joint name="r_leg_hpx" type="revolute">
    <parent link="r_uglut"/>
    <child link="r_lglut"/>
    <origin rpy="0 0 0" xyz="0 0 0"/>
    <axis xyz="1 0 0"/>
    <limit effort="530" lower="-0.523599" upper="0.523599" velocity="12"/>
  </joint>

  <joint name="r_leg_hpy" type="revolute">
    <parent link="r_lglut"/>
    <child link="r_uleg"/>
    <origin rpy="0 0 0" xyz="0.05 -0.0225 -0.066"/>
    <axis xyz="0 1 0"/>
    <limit effort="840" lower="-1.61234" upper="0.65764" velocity="12"/>
  </joint>

  <joint name="r_leg_kny" type="revolute">
    <parent link="r_uleg"/>
    <child link="r_lleg"/>
    <origin rpy="0 0 0" xyz="-0.05 0 -0.374"/>
    <axis xyz="0 1 0"/>
    <limit effort="890" lower="0" upper="2.35637" velocity="12"/>
  </joint>

  <joint name="r_leg_aky" type="revolute">
    <parent link="r_lleg"/>
    <child link="r_talus"/>
    <origin rpy="0 0 0" xyz="0 0 -0.422"/>
    <axis xyz="0 1 0"/>
    <limit effort="740" lower="-1" upper="0.7" velocity="12"/>
  </joint>

  <joint name="r_leg_akx" type="revolute">
    <parent link="r_talus"/>
    <child link="r_foot"/>
    <origin rpy="0 0 0" xyz="0 0 0"/>
    <axis xyz="1 0 0"/>
    <limit effort="360" lower="-0.8" upper="0.8" velocity="12"/>
  </joint>




  <!--                                                              Links                                                          -->
  


  <link name="l_foot"/>

  <link name="l_talus">
    <inertial>
      <mass value="0.125"/>
      <origin rpy="0 0 0" xyz="0 0 0"/>
      <inertia ixx="1.01674e-05" ixy="0" ixz="0" iyy="8.42775e-06" iyz="0" izz="1.30101e-05"/>
    </inertial>
  </link>

  <link name="l_lleg">
    <inertial>
      <mass value="4.515"/>
      <origin rpy="0 0 0" xyz="0.001 0 0.235"/>
      <inertia ixx="0.077" ixy="0" ixz="-0.003" iyy="0.076" iyz="0" izz="0.01"/>
    </inertial>
  </link>

  <link name="l_uleg">
    <inertial>
      <mass value="8.204"/>
      <origin rpy="0 0 0" xyz="0.05 0 0.164"/>
      <inertia ixx="0.09" ixy="0" ixz="0" iyy="0.09" iyz="0" izz="0.02"/>
    </inertial>
  </link>

  <link name="l_lglut">
    <inertial>
      <mass value="0.898"/>
      <origin rpy="0 0 0" xyz="-0.0366659 -0.0054516 0.0347948"/>
      <inertia ixx="0.000691326" ixy="-2.24344e-05" ixz="2.50508e-06" iyy="0.00126856" iyz="0.000137862" izz="0.00106487"/>
    </inertial>
  </link>

  <link name="l_uglut">
    <inertial>
      <mass value="1.959"/>
      <origin rpy="0 0 0" xyz="0.00529262 -0.00344732 0.00313046"/>
      <inertia ixx="0.00074276" ixy="-3.79607e-08" ixz="-2.79549e-05" iyy="0.000688179" iyz="-3.2735e-08" izz="0.00041242"/>
    </inertial>
  </link>

  <link name="pelvis">
    <inertial>
      <mass value="9.509"/>
      <origin rpy="0 0 0" xyz="0.0111 -0.089 0.0271"/>
      <inertia ixx="0.1244" ixy="0.0008" ixz="-0.0007" iyy="0.0958" iyz="-0.0005" izz="0.1167"/>
    </inertial>
  </link>



  <link name="ltorso">
    <inertial>
      <mass value="2.270"/>
      <origin rpy="0 0 0" xyz="-0.0112984 -3.15366e-06 0.0746835"/>
      <inertia ixx="0.0039092" ixy="-5.04491e-08" ixz="-0.000342157" iyy="0.00341694" iyz="4.87119e-07" izz="0.00174492"/>
    </inertial>
  </link>

  <link name="mtorso">
    <inertial>
      <mass value="0.799"/>
      <origin rpy="0 0 0" xyz="-0.00816266 -0.0131245 0.0305974"/>
      <inertia ixx="0.000454181" ixy="-6.10764e-05" ixz="3.94009e-05" iyy="0.000483282" iyz="5.27463e-05" izz="0.000444215"/>
    </inertial>
  </link>

  <link name="utorso">
    <inertial>
      <mass value="84.409"/>
      <origin rpy="0 0 0" xyz="-0.0622 0.0023 0.3157"/>
      <inertia ixx="1.577" ixy="-0.032" ixz="0.102" iyy="1.602" iyz="0.047" izz="0.565"/>
    </inertial>
  </link>



  <link name="l_clav">
    <inertial>
      <mass value="4.466"/>
      <origin rpy="0 0 0" xyz="0 0 -0.084"/>
      <inertia ixx="0.011" ixy="0" ixz="0" iyy="0.009" iyz="-0.004" izz="0.004"/>
    </inertial>
  </link>

  <link name="l_scap">
    <inertial>
      <mass value="3.899"/>
      <origin rpy="0 0 0" xyz="0 0 0"/>
      <inertia ixx="0.00319" ixy="0" ixz="0" iyy="0.00583" iyz="0" izz="0.00583"/>
    </inertial>
  </link>

  <link name="l_uarm">
    <inertial>
      <mass value="4.386"/>
      <origin rpy="0 0 0" xyz="0.0 -0.065 0.0"/>
      <inertia ixx="0.00656" ixy="0" ixz="0" iyy="0.00358" iyz="0" izz="0.00656"/>
    </inertial>
  </link>

  <link name="l_larm">
    <inertial>
      <mass value="3.248"/>
      <origin rpy="0 0 0" xyz="0 0 0"/>
      <inertia ixx="0.00265" ixy="0" ixz="0" iyy="0.00446" iyz="0" izz="0.00446"/>
    </inertial>
  </link>

  <link name="l_ufarm">
    <inertial>
      <mass value="2.4798"/>
      <origin rpy="0 0 0" xyz="0.00015 -0.08296 0.00037"/>
      <inertia ixx="0.012731" ixy="0" ixz="0" iyy="0.002857" iyz="0" izz="0.011948"/>
    </inertial>
  </link>

  <link name="l_lfarm">
    <inertial>
      <mass value="0.648"/>
      <origin rpy="0 0 0" xyz="0.00017 0.02515 0.00163"/>
      <inertia ixx="0.000764" ixy="0" ixz="0" iyy="0.000429" iyz="0" izz="0.000825"/>
    </inertial>
  </link>

  <link name="l_hand">
    <inertial>
      <mass value="0.5839"/>
      <origin rpy="0 0 0" xyz="0.00016 0.08159 0.00002"/>
      <inertia ixx="0.000388" ixy="0" ixz="0" iyy="0.000477" iyz="0" izz="0.000379"/>
    </inertial>
  </link>



  <link name="head">
    <inertial>
      <mass value="1.4199"/>
      <origin rpy="0 0 0" xyz="-0.075493 3.3383E-05 0.02774"/>
      <inertia ixx="0.0039688" ixy="-1.5797E-06" ixz="-0.00089293" iyy="0.0041178" iyz="-6.8415E-07" izz="0.0035243"/>
    </inertial>
  </link>



  <link name="r_clav">
    <inertial>
      <mass value="4.466"/>
      <origin rpy="0 0 0" xyz="0 0 -0.084"/>
      <inertia ixx="0.011" ixy="0" ixz="0" iyy="0.009" iyz="0.004" izz="0.004"/>
    </inertial>
  </link>

  <link name="r_scap">
    <inertial>
      <mass value="3.899"/>
      <origin rpy="0 0 0" xyz="0 0 0"/>
      <inertia ixx="0.00319" ixy="0" ixz="0" iyy="0.00583" iyz="0" izz="0.00583"/>
    </inertial>
  </link>

  <link name="r_uarm">
    <inertial>
      <mass value="4.386"/>
      <origin rpy="0 0 0" xyz="0 0.065 0"/>
      <inertia ixx="0.00656" ixy="0" ixz="0" iyy="0.00358" iyz="0" izz="0.00656"/>
    </inertial>
  </link>

  <link name="r_larm">
    <inertial>
      <mass value="3.248"/>
      <origin rpy="0 0 0" xyz="0 0 0"/>
      <inertia ixx="0.00265" ixy="0" ixz="0" iyy="0.00446" iyz="0" izz="0.00446"/>
    </inertial>
  </link>

  <link name="r_ufarm">
    <inertial>
      <mass value="2.4798"/>
      <origin rpy="0 0 0" xyz="0.00015 0.08296 0.00037"/>
      <inertia ixx="0.012731" ixy="0" ixz="0" iyy="0.002857" iyz="0" izz="0.011948"/>
    </inertial>
  </link>

  <link name="r_lfarm">
    <inertial>
      <mass value="0.648"/>
      <origin rpy="0 0 0" xyz="0.00017 -0.02515 0.00163"/>
      <inertia ixx="0.000764" ixy="0" ixz="0" iyy="0.000429" iyz="0" izz="0.000825"/>
    </inertial>
  </link>

  <link name="r_hand">
    <inertial>
      <mass value="0.5839"/>
      <origin rpy="0 0 0" xyz="0.00016 -0.08159 0.00002"/>
      <inertia ixx="0.000388" ixy="0" ixz="0" iyy="0.000477" iyz="0" izz="0.000379"/>
    </inertial>
  </link>



  <link name="r_uglut">
    <inertial>
      <mass value="1.959"/>
      <origin rpy="0 0 0" xyz="0.00529262 0.00344732 0.00313046"/>
      <inertia ixx="0.00074276" ixy="3.79607e-08" ixz="-2.79549e-05" iyy="0.000688179" iyz="3.2735e-08" izz="0.00041242"/>
    </inertial>
  </link>

  <link name="r_lglut">
    <inertial>
      <mass value="0.898"/>
      <origin rpy="0 0 0" xyz="0.0133341 -0.0170484 -0.0312052"/>
      <inertia ixx="0.000691326" ixy="2.24344e-05" ixz="2.50508e-06" iyy="0.00126856" iyz="-0.000137862" izz="0.00106487"/>
    </inertial>
  </link>

  <link name="r_uleg">
    <inertial>
      <mass value="8.204"/>
      <origin rpy="0 0 0" xyz="0 0 -0.21"/>
      <inertia ixx="0.09" ixy="0" ixz="0" iyy="0.09" iyz="0" izz="0.02"/>
    </inertial>
  </link>

  <link name="r_lleg">
    <inertial>
      <mass value="4.515"/>
      <origin rpy="0 0 0" xyz="0.001 0 -0.187"/>
      <inertia ixx="0.077" ixy="-0" ixz="-0.003" iyy="0.076" iyz="-0" izz="0.01"/>
    </inertial>
  </link>

  <link name="r_talus">
    <inertial>
      <mass value="0.125"/>
      <origin rpy="0 0 0" xyz="0 0 0"/>
      <inertia ixx="1.01674e-05" ixy="0" ixz="0" iyy="8.42775e-06" iyz="0" izz="1.30101e-05"/>
    </inertial>
  </link>

  <link name="r_foot">
    <inertial>
      <mass value="2.41"/>
      <origin rpy="0 0 0" xyz="0.027 0 -0.067"/>
      <inertia ixx="0.002" ixy="0" ixz="0" iyy="0.007" iyz="0" izz="0.008"/>
    </inertial>
  </link>



</robot>
